2020-05-13 19:01:48,206 ERROR: Exception on /index [GET] [in C:\Users\Baraban\PycharmProjects\socnet\untitled2\lib\site-packages\flask\app.py:1761]
Traceback (most recent call last):
  File "C:\Users\Baraban\PycharmProjects\socnet\untitled2\lib\site-packages\flask\app.py", line 2292, in wsgi_app
    response = self.full_dispatch_request()
  File "C:\Users\Baraban\PycharmProjects\socnet\untitled2\lib\site-packages\flask\app.py", line 1815, in full_dispatch_request
    rv = self.handle_user_exception(e)
  File "C:\Users\Baraban\PycharmProjects\socnet\untitled2\lib\site-packages\flask\app.py", line 1718, in handle_user_exception
    reraise(exc_type, exc_value, tb)
  File "C:\Users\Baraban\PycharmProjects\socnet\untitled2\lib\site-packages\flask\_compat.py", line 35, in reraise
    raise value
  File "C:\Users\Baraban\PycharmProjects\socnet\untitled2\lib\site-packages\flask\app.py", line 1813, in full_dispatch_request
    rv = self.dispatch_request()
  File "C:\Users\Baraban\PycharmProjects\socnet\untitled2\lib\site-packages\flask\app.py", line 1799, in dispatch_request
    return self.view_functions[rule.endpoint](**req.view_args)
  File "C:\Users\Baraban\PycharmProjects\untitled2\app\main\routes.py", line 20, in index
    argg = request.args.get.values()
AttributeError: 'function' object has no attribute 'values'
2020-05-13 19:03:08,967 INFO: Microblog startup [in C:\Users\Baraban\PycharmProjects\untitled2\app\__init__.py:72]
2020-05-13 19:03:09,176 ERROR: Exception on /index [GET] [in C:\Users\Baraban\PycharmProjects\socnet\untitled2\lib\site-packages\flask\app.py:1761]
Traceback (most recent call last):
  File "C:\Users\Baraban\PycharmProjects\socnet\untitled2\lib\site-packages\flask\app.py", line 2292, in wsgi_app
    response = self.full_dispatch_request()
  File "C:\Users\Baraban\PycharmProjects\socnet\untitled2\lib\site-packages\flask\app.py", line 1815, in full_dispatch_request
    rv = self.handle_user_exception(e)
  File "C:\Users\Baraban\PycharmProjects\socnet\untitled2\lib\site-packages\flask\app.py", line 1718, in handle_user_exception
    reraise(exc_type, exc_value, tb)
  File "C:\Users\Baraban\PycharmProjects\socnet\untitled2\lib\site-packages\flask\_compat.py", line 35, in reraise
    raise value
  File "C:\Users\Baraban\PycharmProjects\socnet\untitled2\lib\site-packages\flask\app.py", line 1813, in full_dispatch_request
    rv = self.dispatch_request()
  File "C:\Users\Baraban\PycharmProjects\socnet\untitled2\lib\site-packages\flask\app.py", line 1799, in dispatch_request
    return self.view_functions[rule.endpoint](**req.view_args)
  File "C:\Users\Baraban\PycharmProjects\untitled2\app\main\routes.py", line 20, in index
    argg = request.values()
TypeError: 'CombinedMultiDict' object is not callable
2020-05-13 19:03:34,883 INFO: Microblog startup [in C:\Users\Baraban\PycharmProjects\untitled2\app\__init__.py:72]
2020-05-13 19:04:09,131 ERROR: Exception on /index [GET] [in C:\Users\Baraban\PycharmProjects\socnet\untitled2\lib\site-packages\flask\app.py:1761]
Traceback (most recent call last):
  File "C:\Users\Baraban\PycharmProjects\socnet\untitled2\lib\site-packages\flask\app.py", line 2292, in wsgi_app
    response = self.full_dispatch_request()
  File "C:\Users\Baraban\PycharmProjects\socnet\untitled2\lib\site-packages\flask\app.py", line 1815, in full_dispatch_request
    rv = self.handle_user_exception(e)
  File "C:\Users\Baraban\PycharmProjects\socnet\untitled2\lib\site-packages\flask\app.py", line 1718, in handle_user_exception
    reraise(exc_type, exc_value, tb)
  File "C:\Users\Baraban\PycharmProjects\socnet\untitled2\lib\site-packages\flask\_compat.py", line 35, in reraise
    raise value
  File "C:\Users\Baraban\PycharmProjects\socnet\untitled2\lib\site-packages\flask\app.py", line 1813, in full_dispatch_request
    rv = self.dispatch_request()
  File "C:\Users\Baraban\PycharmProjects\socnet\untitled2\lib\site-packages\flask\app.py", line 1799, in dispatch_request
    return self.view_functions[rule.endpoint](**req.view_args)
  File "C:\Users\Baraban\PycharmProjects\untitled2\app\main\routes.py", line 22, in index
    bibas = argg.fromkeys()
AttributeError: 'dict_valueiterator' object has no attribute 'fromkeys'
2020-05-13 19:06:41,065 INFO: Microblog startup [in C:\Users\Baraban\PycharmProjects\untitled2\app\__init__.py:72]
2020-05-13 19:06:41,251 ERROR: Exception on /index [GET] [in C:\Users\Baraban\PycharmProjects\socnet\untitled2\lib\site-packages\flask\app.py:1761]
Traceback (most recent call last):
  File "C:\Users\Baraban\PycharmProjects\socnet\untitled2\lib\site-packages\flask\app.py", line 2292, in wsgi_app
    response = self.full_dispatch_request()
  File "C:\Users\Baraban\PycharmProjects\socnet\untitled2\lib\site-packages\flask\app.py", line 1815, in full_dispatch_request
    rv = self.handle_user_exception(e)
  File "C:\Users\Baraban\PycharmProjects\socnet\untitled2\lib\site-packages\flask\app.py", line 1718, in handle_user_exception
    reraise(exc_type, exc_value, tb)
  File "C:\Users\Baraban\PycharmProjects\socnet\untitled2\lib\site-packages\flask\_compat.py", line 35, in reraise
    raise value
  File "C:\Users\Baraban\PycharmProjects\socnet\untitled2\lib\site-packages\flask\app.py", line 1813, in full_dispatch_request
    rv = self.dispatch_request()
  File "C:\Users\Baraban\PycharmProjects\socnet\untitled2\lib\site-packages\flask\app.py", line 1799, in dispatch_request
    return self.view_functions[rule.endpoint](**req.view_args)
  File "C:\Users\Baraban\PycharmProjects\untitled2\app\main\routes.py", line 20, in index
    ass = request.args.get()
TypeError: get() missing 1 required positional argument: 'key'
2020-05-13 19:07:16,788 INFO: Microblog startup [in C:\Users\Baraban\PycharmProjects\untitled2\app\__init__.py:72]
2020-05-13 19:11:40,038 INFO: Microblog startup [in C:\Users\Baraban\PycharmProjects\untitled2\app\__init__.py:72]
2020-05-13 19:11:48,605 ERROR: Exception on /index [GET] [in C:\Users\Baraban\PycharmProjects\socnet\untitled2\lib\site-packages\flask\app.py:1761]
Traceback (most recent call last):
  File "C:\Users\Baraban\PycharmProjects\socnet\untitled2\lib\site-packages\flask\app.py", line 2292, in wsgi_app
    response = self.full_dispatch_request()
  File "C:\Users\Baraban\PycharmProjects\socnet\untitled2\lib\site-packages\flask\app.py", line 1815, in full_dispatch_request
    rv = self.handle_user_exception(e)
  File "C:\Users\Baraban\PycharmProjects\socnet\untitled2\lib\site-packages\flask\app.py", line 1718, in handle_user_exception
    reraise(exc_type, exc_value, tb)
  File "C:\Users\Baraban\PycharmProjects\socnet\untitled2\lib\site-packages\flask\_compat.py", line 35, in reraise
    raise value
  File "C:\Users\Baraban\PycharmProjects\socnet\untitled2\lib\site-packages\flask\app.py", line 1813, in full_dispatch_request
    rv = self.dispatch_request()
  File "C:\Users\Baraban\PycharmProjects\socnet\untitled2\lib\site-packages\flask\app.py", line 1799, in dispatch_request
    return self.view_functions[rule.endpoint](**req.view_args)
  File "C:\Users\Baraban\PycharmProjects\untitled2\app\main\routes.py", line 20, in index
    argg = request.args()
TypeError: 'ImmutableMultiDict' object is not callable
2020-05-13 19:12:17,916 INFO: Microblog startup [in C:\Users\Baraban\PycharmProjects\untitled2\app\__init__.py:72]
2020-05-13 19:12:32,110 ERROR: Exception on /index [GET] [in C:\Users\Baraban\PycharmProjects\socnet\untitled2\lib\site-packages\flask\app.py:1761]
Traceback (most recent call last):
  File "C:\Users\Baraban\PycharmProjects\socnet\untitled2\lib\site-packages\flask\app.py", line 2292, in wsgi_app
    response = self.full_dispatch_request()
  File "C:\Users\Baraban\PycharmProjects\socnet\untitled2\lib\site-packages\flask\app.py", line 1815, in full_dispatch_request
    rv = self.handle_user_exception(e)
  File "C:\Users\Baraban\PycharmProjects\socnet\untitled2\lib\site-packages\flask\app.py", line 1718, in handle_user_exception
    reraise(exc_type, exc_value, tb)
  File "C:\Users\Baraban\PycharmProjects\socnet\untitled2\lib\site-packages\flask\_compat.py", line 35, in reraise
    raise value
  File "C:\Users\Baraban\PycharmProjects\socnet\untitled2\lib\site-packages\flask\app.py", line 1813, in full_dispatch_request
    rv = self.dispatch_request()
  File "C:\Users\Baraban\PycharmProjects\socnet\untitled2\lib\site-packages\flask\app.py", line 1799, in dispatch_request
    return self.view_functions[rule.endpoint](**req.view_args)
  File "C:\Users\Baraban\PycharmProjects\untitled2\app\main\routes.py", line 21, in index
    for key,value in argg:
ValueError: too many values to unpack (expected 2)
2020-05-13 19:12:32,117 ERROR: Exception on /index [GET] [in C:\Users\Baraban\PycharmProjects\socnet\untitled2\lib\site-packages\flask\app.py:1761]
Traceback (most recent call last):
  File "C:\Users\Baraban\PycharmProjects\socnet\untitled2\lib\site-packages\flask\app.py", line 2292, in wsgi_app
    response = self.full_dispatch_request()
  File "C:\Users\Baraban\PycharmProjects\socnet\untitled2\lib\site-packages\flask\app.py", line 1815, in full_dispatch_request
    rv = self.handle_user_exception(e)
  File "C:\Users\Baraban\PycharmProjects\socnet\untitled2\lib\site-packages\flask\app.py", line 1718, in handle_user_exception
    reraise(exc_type, exc_value, tb)
  File "C:\Users\Baraban\PycharmProjects\socnet\untitled2\lib\site-packages\flask\_compat.py", line 35, in reraise
    raise value
  File "C:\Users\Baraban\PycharmProjects\socnet\untitled2\lib\site-packages\flask\app.py", line 1813, in full_dispatch_request
    rv = self.dispatch_request()
  File "C:\Users\Baraban\PycharmProjects\socnet\untitled2\lib\site-packages\flask\app.py", line 1799, in dispatch_request
    return self.view_functions[rule.endpoint](**req.view_args)
  File "C:\Users\Baraban\PycharmProjects\untitled2\app\main\routes.py", line 21, in index
    for key,value in argg:
ValueError: too many values to unpack (expected 2)
2020-05-13 19:13:35,489 INFO: Microblog startup [in C:\Users\Baraban\PycharmProjects\untitled2\app\__init__.py:72]
