2019-12-24 06:50:19,814 ERROR: Exception on /delete_profile/10 [GET] [in C:\Users\Baraban\PycharmProjects\socnet\untitled2\lib\site-packages\flask\app.py:1761]
Traceback (most recent call last):
  File "C:\Users\Baraban\PycharmProjects\socnet\untitled2\lib\site-packages\flask\app.py", line 2292, in wsgi_app
    response = self.full_dispatch_request()
  File "C:\Users\Baraban\PycharmProjects\socnet\untitled2\lib\site-packages\flask\app.py", line 1815, in full_dispatch_request
    rv = self.handle_user_exception(e)
  File "C:\Users\Baraban\PycharmProjects\socnet\untitled2\lib\site-packages\flask\app.py", line 1718, in handle_user_exception
    reraise(exc_type, exc_value, tb)
  File "C:\Users\Baraban\PycharmProjects\socnet\untitled2\lib\site-packages\flask\_compat.py", line 35, in reraise
    raise value
  File "C:\Users\Baraban\PycharmProjects\socnet\untitled2\lib\site-packages\flask\app.py", line 1813, in full_dispatch_request
    rv = self.dispatch_request()
  File "C:\Users\Baraban\PycharmProjects\socnet\untitled2\lib\site-packages\flask\app.py", line 1799, in dispatch_request
    return self.view_functions[rule.endpoint](**req.view_args)
  File "C:\Users\Baraban\PycharmProjects\socnet\untitled2\lib\site-packages\flask_login\utils.py", line 228, in decorated_view
    return func(*args, **kwargs)
  File "C:\Users\Baraban\PycharmProjects\untitled2\app\main\routes.py", line 425, in delete_profile
    [id])
psycopg2.errors.ForeignKeyViolation: update or delete on table "uzer" violates foreign key constraint "post_idavtor_fkey" on table "post"
DETAIL:  Key (iduser)=(10) is still referenced from table "post".

2019-12-24 06:50:58,102 INFO: Microblog startup [in C:\Users\Baraban\PycharmProjects\untitled2\app\__init__.py:72]
2019-12-24 06:51:01,807 ERROR: Exception on /delete_profile/10 [GET] [in C:\Users\Baraban\PycharmProjects\socnet\untitled2\lib\site-packages\flask\app.py:1761]
Traceback (most recent call last):
  File "C:\Users\Baraban\PycharmProjects\socnet\untitled2\lib\site-packages\flask\app.py", line 2292, in wsgi_app
    response = self.full_dispatch_request()
  File "C:\Users\Baraban\PycharmProjects\socnet\untitled2\lib\site-packages\flask\app.py", line 1815, in full_dispatch_request
    rv = self.handle_user_exception(e)
  File "C:\Users\Baraban\PycharmProjects\socnet\untitled2\lib\site-packages\flask\app.py", line 1718, in handle_user_exception
    reraise(exc_type, exc_value, tb)
  File "C:\Users\Baraban\PycharmProjects\socnet\untitled2\lib\site-packages\flask\_compat.py", line 35, in reraise
    raise value
  File "C:\Users\Baraban\PycharmProjects\socnet\untitled2\lib\site-packages\flask\app.py", line 1813, in full_dispatch_request
    rv = self.dispatch_request()
  File "C:\Users\Baraban\PycharmProjects\socnet\untitled2\lib\site-packages\flask\app.py", line 1799, in dispatch_request
    return self.view_functions[rule.endpoint](**req.view_args)
  File "C:\Users\Baraban\PycharmProjects\socnet\untitled2\lib\site-packages\flask_login\utils.py", line 228, in decorated_view
    return func(*args, **kwargs)
  File "C:\Users\Baraban\PycharmProjects\untitled2\app\main\routes.py", line 429, in delete_profile
    [id])
psycopg2.errors.ForeignKeyViolation: update or delete on table "uzer" violates foreign key constraint "post_idavtor_fkey" on table "post"
DETAIL:  Key (iduser)=(10) is still referenced from table "post".

2019-12-24 06:51:55,061 INFO: Microblog startup [in C:\Users\Baraban\PycharmProjects\untitled2\app\__init__.py:72]
2019-12-24 06:52:10,343 ERROR: Exception on /delete_profile/10 [GET] [in C:\Users\Baraban\PycharmProjects\socnet\untitled2\lib\site-packages\flask\app.py:1761]
Traceback (most recent call last):
  File "C:\Users\Baraban\PycharmProjects\socnet\untitled2\lib\site-packages\flask\app.py", line 2292, in wsgi_app
    response = self.full_dispatch_request()
  File "C:\Users\Baraban\PycharmProjects\socnet\untitled2\lib\site-packages\flask\app.py", line 1815, in full_dispatch_request
    rv = self.handle_user_exception(e)
  File "C:\Users\Baraban\PycharmProjects\socnet\untitled2\lib\site-packages\flask\app.py", line 1718, in handle_user_exception
    reraise(exc_type, exc_value, tb)
  File "C:\Users\Baraban\PycharmProjects\socnet\untitled2\lib\site-packages\flask\_compat.py", line 35, in reraise
    raise value
  File "C:\Users\Baraban\PycharmProjects\socnet\untitled2\lib\site-packages\flask\app.py", line 1813, in full_dispatch_request
    rv = self.dispatch_request()
  File "C:\Users\Baraban\PycharmProjects\socnet\untitled2\lib\site-packages\flask\app.py", line 1799, in dispatch_request
    return self.view_functions[rule.endpoint](**req.view_args)
  File "C:\Users\Baraban\PycharmProjects\socnet\untitled2\lib\site-packages\flask_login\utils.py", line 228, in decorated_view
    return func(*args, **kwargs)
  File "C:\Users\Baraban\PycharmProjects\untitled2\app\main\routes.py", line 421, in delete_profile
    [id,id])
psycopg2.errors.ForeignKeyViolation: update or delete on table "post" violates foreign key constraint "com_idpost_fkey" on table "com"
DETAIL:  Key (idpost)=(37) is still referenced from table "com".

2019-12-24 06:52:43,232 INFO: Microblog startup [in C:\Users\Baraban\PycharmProjects\untitled2\app\__init__.py:72]
2019-12-24 06:52:47,697 ERROR: Exception on /delete_profile/10 [GET] [in C:\Users\Baraban\PycharmProjects\socnet\untitled2\lib\site-packages\flask\app.py:1761]
Traceback (most recent call last):
  File "C:\Users\Baraban\PycharmProjects\socnet\untitled2\lib\site-packages\flask\app.py", line 2292, in wsgi_app
    response = self.full_dispatch_request()
  File "C:\Users\Baraban\PycharmProjects\socnet\untitled2\lib\site-packages\flask\app.py", line 1815, in full_dispatch_request
    rv = self.handle_user_exception(e)
  File "C:\Users\Baraban\PycharmProjects\socnet\untitled2\lib\site-packages\flask\app.py", line 1718, in handle_user_exception
    reraise(exc_type, exc_value, tb)
  File "C:\Users\Baraban\PycharmProjects\socnet\untitled2\lib\site-packages\flask\_compat.py", line 35, in reraise
    raise value
  File "C:\Users\Baraban\PycharmProjects\socnet\untitled2\lib\site-packages\flask\app.py", line 1813, in full_dispatch_request
    rv = self.dispatch_request()
  File "C:\Users\Baraban\PycharmProjects\socnet\untitled2\lib\site-packages\flask\app.py", line 1799, in dispatch_request
    return self.view_functions[rule.endpoint](**req.view_args)
  File "C:\Users\Baraban\PycharmProjects\socnet\untitled2\lib\site-packages\flask_login\utils.py", line 228, in decorated_view
    return func(*args, **kwargs)
  File "C:\Users\Baraban\PycharmProjects\untitled2\app\main\routes.py", line 421, in delete_profile
    [id,id])
psycopg2.errors.ForeignKeyViolation: update or delete on table "post" violates foreign key constraint "com_idpost_fkey" on table "com"
DETAIL:  Key (idpost)=(37) is still referenced from table "com".

2019-12-24 06:58:27,316 ERROR: Exception on /user/id2 [GET] [in C:\Users\Baraban\PycharmProjects\socnet\untitled2\lib\site-packages\flask\app.py:1761]
Traceback (most recent call last):
  File "C:\Users\Baraban\PycharmProjects\socnet\untitled2\lib\site-packages\flask\app.py", line 2292, in wsgi_app
    response = self.full_dispatch_request()
  File "C:\Users\Baraban\PycharmProjects\socnet\untitled2\lib\site-packages\flask\app.py", line 1815, in full_dispatch_request
    rv = self.handle_user_exception(e)
  File "C:\Users\Baraban\PycharmProjects\socnet\untitled2\lib\site-packages\flask\app.py", line 1718, in handle_user_exception
    reraise(exc_type, exc_value, tb)
  File "C:\Users\Baraban\PycharmProjects\socnet\untitled2\lib\site-packages\flask\_compat.py", line 35, in reraise
    raise value
  File "C:\Users\Baraban\PycharmProjects\socnet\untitled2\lib\site-packages\flask\app.py", line 1813, in full_dispatch_request
    rv = self.dispatch_request()
  File "C:\Users\Baraban\PycharmProjects\socnet\untitled2\lib\site-packages\flask\app.py", line 1799, in dispatch_request
    return self.view_functions[rule.endpoint](**req.view_args)
  File "C:\Users\Baraban\PycharmProjects\socnet\untitled2\lib\site-packages\flask_login\utils.py", line 228, in decorated_view
    return func(*args, **kwargs)
  File "C:\Users\Baraban\PycharmProjects\untitled2\app\main\routes.py", line 74, in user
    [id])
psycopg2.errors.InFailedSqlTransaction: current transaction is aborted, commands ignored until end of transaction block

2019-12-24 06:58:47,037 ERROR: Exception on /user/id5 [GET] [in C:\Users\Baraban\PycharmProjects\socnet\untitled2\lib\site-packages\flask\app.py:1761]
Traceback (most recent call last):
  File "C:\Users\Baraban\PycharmProjects\socnet\untitled2\lib\site-packages\flask\app.py", line 2292, in wsgi_app
    response = self.full_dispatch_request()
  File "C:\Users\Baraban\PycharmProjects\socnet\untitled2\lib\site-packages\flask\app.py", line 1815, in full_dispatch_request
    rv = self.handle_user_exception(e)
  File "C:\Users\Baraban\PycharmProjects\socnet\untitled2\lib\site-packages\flask\app.py", line 1718, in handle_user_exception
    reraise(exc_type, exc_value, tb)
  File "C:\Users\Baraban\PycharmProjects\socnet\untitled2\lib\site-packages\flask\_compat.py", line 35, in reraise
    raise value
  File "C:\Users\Baraban\PycharmProjects\socnet\untitled2\lib\site-packages\flask\app.py", line 1813, in full_dispatch_request
    rv = self.dispatch_request()
  File "C:\Users\Baraban\PycharmProjects\socnet\untitled2\lib\site-packages\flask\app.py", line 1799, in dispatch_request
    return self.view_functions[rule.endpoint](**req.view_args)
  File "C:\Users\Baraban\PycharmProjects\socnet\untitled2\lib\site-packages\flask_login\utils.py", line 228, in decorated_view
    return func(*args, **kwargs)
  File "C:\Users\Baraban\PycharmProjects\untitled2\app\main\routes.py", line 74, in user
    [id])
psycopg2.errors.InFailedSqlTransaction: current transaction is aborted, commands ignored until end of transaction block

