2019-12-24 06:43:57,936 ERROR: Exception on /delete_profile/10 [GET] [in C:\Users\Baraban\PycharmProjects\socnet\untitled2\lib\site-packages\flask\app.py:1761]
Traceback (most recent call last):
  File "C:\Users\Baraban\PycharmProjects\socnet\untitled2\lib\site-packages\flask\app.py", line 2292, in wsgi_app
    response = self.full_dispatch_request()
  File "C:\Users\Baraban\PycharmProjects\socnet\untitled2\lib\site-packages\flask\app.py", line 1815, in full_dispatch_request
    rv = self.handle_user_exception(e)
  File "C:\Users\Baraban\PycharmProjects\socnet\untitled2\lib\site-packages\flask\app.py", line 1718, in handle_user_exception
    reraise(exc_type, exc_value, tb)
  File "C:\Users\Baraban\PycharmProjects\socnet\untitled2\lib\site-packages\flask\_compat.py", line 35, in reraise
    raise value
  File "C:\Users\Baraban\PycharmProjects\socnet\untitled2\lib\site-packages\flask\app.py", line 1813, in full_dispatch_request
    rv = self.dispatch_request()
  File "C:\Users\Baraban\PycharmProjects\socnet\untitled2\lib\site-packages\flask\app.py", line 1799, in dispatch_request
    return self.view_functions[rule.endpoint](**req.view_args)
  File "C:\Users\Baraban\PycharmProjects\socnet\untitled2\lib\site-packages\flask_login\utils.py", line 228, in decorated_view
    return func(*args, **kwargs)
  File "C:\Users\Baraban\PycharmProjects\untitled2\app\main\routes.py", line 413, in delete_profile
    [id])
psycopg2.errors.ForeignKeyViolation: update or delete on table "uzer" violates foreign key constraint "vo_iduser_fkey" on table "vo"
DETAIL:  Key (iduser)=(10) is still referenced from table "vo".

2019-12-24 06:44:47,398 INFO: Microblog startup [in C:\Users\Baraban\PycharmProjects\untitled2\app\__init__.py:72]
2019-12-24 06:44:54,378 ERROR: Exception on /delete_profile/10 [GET] [in C:\Users\Baraban\PycharmProjects\socnet\untitled2\lib\site-packages\flask\app.py:1761]
Traceback (most recent call last):
  File "C:\Users\Baraban\PycharmProjects\socnet\untitled2\lib\site-packages\flask\app.py", line 2292, in wsgi_app
    response = self.full_dispatch_request()
  File "C:\Users\Baraban\PycharmProjects\socnet\untitled2\lib\site-packages\flask\app.py", line 1815, in full_dispatch_request
    rv = self.handle_user_exception(e)
  File "C:\Users\Baraban\PycharmProjects\socnet\untitled2\lib\site-packages\flask\app.py", line 1718, in handle_user_exception
    reraise(exc_type, exc_value, tb)
  File "C:\Users\Baraban\PycharmProjects\socnet\untitled2\lib\site-packages\flask\_compat.py", line 35, in reraise
    raise value
  File "C:\Users\Baraban\PycharmProjects\socnet\untitled2\lib\site-packages\flask\app.py", line 1813, in full_dispatch_request
    rv = self.dispatch_request()
  File "C:\Users\Baraban\PycharmProjects\socnet\untitled2\lib\site-packages\flask\app.py", line 1799, in dispatch_request
    return self.view_functions[rule.endpoint](**req.view_args)
  File "C:\Users\Baraban\PycharmProjects\socnet\untitled2\lib\site-packages\flask_login\utils.py", line 228, in decorated_view
    return func(*args, **kwargs)
  File "C:\Users\Baraban\PycharmProjects\untitled2\app\main\routes.py", line 416, in delete_profile
    [id])
psycopg2.errors.ForeignKeyViolation: update or delete on table "uzer" violates foreign key constraint "post_idavtor_fkey" on table "post"
DETAIL:  Key (iduser)=(10) is still referenced from table "post".

2019-12-24 06:47:42,840 INFO: Microblog startup [in C:\Users\Baraban\PycharmProjects\untitled2\app\__init__.py:72]
2019-12-24 06:47:50,579 ERROR: Exception on /delete_profile/10 [GET] [in C:\Users\Baraban\PycharmProjects\socnet\untitled2\lib\site-packages\flask\app.py:1761]
Traceback (most recent call last):
  File "C:\Users\Baraban\PycharmProjects\socnet\untitled2\lib\site-packages\flask\app.py", line 2292, in wsgi_app
    response = self.full_dispatch_request()
  File "C:\Users\Baraban\PycharmProjects\socnet\untitled2\lib\site-packages\flask\app.py", line 1815, in full_dispatch_request
    rv = self.handle_user_exception(e)
  File "C:\Users\Baraban\PycharmProjects\socnet\untitled2\lib\site-packages\flask\app.py", line 1718, in handle_user_exception
    reraise(exc_type, exc_value, tb)
  File "C:\Users\Baraban\PycharmProjects\socnet\untitled2\lib\site-packages\flask\_compat.py", line 35, in reraise
    raise value
  File "C:\Users\Baraban\PycharmProjects\socnet\untitled2\lib\site-packages\flask\app.py", line 1813, in full_dispatch_request
    rv = self.dispatch_request()
  File "C:\Users\Baraban\PycharmProjects\socnet\untitled2\lib\site-packages\flask\app.py", line 1799, in dispatch_request
    return self.view_functions[rule.endpoint](**req.view_args)
  File "C:\Users\Baraban\PycharmProjects\socnet\untitled2\lib\site-packages\flask_login\utils.py", line 228, in decorated_view
    return func(*args, **kwargs)
  File "C:\Users\Baraban\PycharmProjects\untitled2\app\main\routes.py", line 413, in delete_profile
    [id])
psycopg2.errors.UndefinedColumn: column "iduser" does not exist
LINE 1: DELETE FROM addfriend WHERE iduser = '10'
                                    ^
HINT:  Perhaps you meant to reference the column "addfriend.id1user" or the column "addfriend.id2user".

2019-12-24 06:48:38,221 INFO: Microblog startup [in C:\Users\Baraban\PycharmProjects\untitled2\app\__init__.py:72]
2019-12-24 06:48:39,808 ERROR: Exception on /delete_profile/10 [GET] [in C:\Users\Baraban\PycharmProjects\socnet\untitled2\lib\site-packages\flask\app.py:1761]
Traceback (most recent call last):
  File "C:\Users\Baraban\PycharmProjects\socnet\untitled2\lib\site-packages\flask\app.py", line 2292, in wsgi_app
    response = self.full_dispatch_request()
  File "C:\Users\Baraban\PycharmProjects\socnet\untitled2\lib\site-packages\flask\app.py", line 1815, in full_dispatch_request
    rv = self.handle_user_exception(e)
  File "C:\Users\Baraban\PycharmProjects\socnet\untitled2\lib\site-packages\flask\app.py", line 1718, in handle_user_exception
    reraise(exc_type, exc_value, tb)
  File "C:\Users\Baraban\PycharmProjects\socnet\untitled2\lib\site-packages\flask\_compat.py", line 35, in reraise
    raise value
  File "C:\Users\Baraban\PycharmProjects\socnet\untitled2\lib\site-packages\flask\app.py", line 1813, in full_dispatch_request
    rv = self.dispatch_request()
  File "C:\Users\Baraban\PycharmProjects\socnet\untitled2\lib\site-packages\flask\app.py", line 1799, in dispatch_request
    return self.view_functions[rule.endpoint](**req.view_args)
  File "C:\Users\Baraban\PycharmProjects\socnet\untitled2\lib\site-packages\flask_login\utils.py", line 228, in decorated_view
    return func(*args, **kwargs)
  File "C:\Users\Baraban\PycharmProjects\untitled2\app\main\routes.py", line 413, in delete_profile
    [id])
IndexError: list index out of range
2019-12-24 06:49:22,659 INFO: Microblog startup [in C:\Users\Baraban\PycharmProjects\untitled2\app\__init__.py:72]
2019-12-24 06:49:24,805 ERROR: Exception on /delete_profile/10 [GET] [in C:\Users\Baraban\PycharmProjects\socnet\untitled2\lib\site-packages\flask\app.py:1761]
Traceback (most recent call last):
  File "C:\Users\Baraban\PycharmProjects\socnet\untitled2\lib\site-packages\flask\app.py", line 2292, in wsgi_app
    response = self.full_dispatch_request()
  File "C:\Users\Baraban\PycharmProjects\socnet\untitled2\lib\site-packages\flask\app.py", line 1815, in full_dispatch_request
    rv = self.handle_user_exception(e)
  File "C:\Users\Baraban\PycharmProjects\socnet\untitled2\lib\site-packages\flask\app.py", line 1718, in handle_user_exception
    reraise(exc_type, exc_value, tb)
  File "C:\Users\Baraban\PycharmProjects\socnet\untitled2\lib\site-packages\flask\_compat.py", line 35, in reraise
    raise value
  File "C:\Users\Baraban\PycharmProjects\socnet\untitled2\lib\site-packages\flask\app.py", line 1813, in full_dispatch_request
    rv = self.dispatch_request()
  File "C:\Users\Baraban\PycharmProjects\socnet\untitled2\lib\site-packages\flask\app.py", line 1799, in dispatch_request
    return self.view_functions[rule.endpoint](**req.view_args)
  File "C:\Users\Baraban\PycharmProjects\socnet\untitled2\lib\site-packages\flask_login\utils.py", line 228, in decorated_view
    return func(*args, **kwargs)
  File "C:\Users\Baraban\PycharmProjects\untitled2\app\main\routes.py", line 416, in delete_profile
    [id])
psycopg2.errors.UndefinedColumn: column "iduser" does not exist
LINE 1: DELETE FROM com WHERE iduser = '10'
                              ^

2019-12-24 06:50:06,676 INFO: Microblog startup [in C:\Users\Baraban\PycharmProjects\untitled2\app\__init__.py:72]
2019-12-24 06:50:13,763 INFO: Microblog startup [in C:\Users\Baraban\PycharmProjects\untitled2\app\__init__.py:72]
